Workbook

Sheet Raw_Data (Before)
A1: Employee Records — Raw Data (Before Cleaning)
A2: 420 employee records as originally entered, containing realistic data-entry errors
A4: EmployeeID | B4: FullName | C4: Department | D4: Gender | E4: Age | F4: MonthlySalary | G4: HireDate | H4: Email | I4: Status
A5: EMP0038 | B5: Yusuf Ogundipe | C5: Fin. | D5: female | E5: 38 | F5: -784644 | G5: 2018-02-21 | H5: yusuf.ogundipe@company.com | I5: active
A6: EMP0375 | B6: Esther Abubakar | C6: Marketing | D6: m | E6: 53 | F6: 235107 | G6: 29-Mar-2019 | H6: esther.abubakar@company.com | I6: Act.
A7: EMP0110 | B7: CHINEDU ADAMU | C7: CS | D7: MALE | E7: 56 | F7: 204175 | G7: 02-Dec-2022 | H7: chinedu.adamu@company.com | I7: Active
A8: EMP0046 | B8: yusuf nwosu | C8: InfoTech | D8: MALE | E8: 36 | F8: 175121 | G8: 17/10/2022 | H8: yusuf.nwosu@company.com | I8: Terminated
A9: EMP0092 | B9: ahmed umeh | C9: OPERATIONS | D9: F | E9: 41 | F9: 886603 | G9: 18-Jul-2018 | H9: ahmed.umeh@company.com | I9: ACTIVE
A10: EMP0324 | B10: Daniel Ajayi | C10: IT | D10: f | E10: 50 | F10: 332625 | G10: 29-Feb-2020 | H10: daniel.ajayi@company.com | I10: Active
A11: EMP0098 | B11: Hauwa Nwosu | C11: Ops | D11: Male | E11: 36 | F11: 424011 | G11: 05-Oct-2024 | H11: hauwa.nwosu@company.com | I11: INACTIVE
A12: EMP0326 | B12: samuel bello | C12: Finance | D12: MALE | E12: 40 | F12: 138360 | G12: 2022-06-13 | H12: samuel.bello@company.com | I12: ACTIVE
A13: EMP0358 | B13: Peter Chukwu | C13: Marketing | D13: f | E13: 57 | F13: 94473 | G13: 06-Dec-2022 | H13: peter.chukwu@company.com | I13: Active
A14: EMP0266 | B14: Bisi Uche | C14: OPERATIONS | D14: Female | E14: 49 | F14: 50265600 | G14: 19-Mar-2020 | H14: bisi.uche@company.com | I14: Act.
A15: EMP0156 | B15: Aisha Lawal | C15: Sales | D15: MALE | E15: 59 | F15: 196419 | G15: 2022-09-08 | H15: aisha.lawal@company.com | I15: active
A16: EMP0217 | B16: ola ogundipe | C16: InfoTech | D16: m | E16: 49 | F16: 271152 | G16: 16/01/2022 | H16: ola.ogundipe@company.com | I16: active
... A19: EMP0281 | B19: AMAKA NNAMDI | C19: I.T. | D19: Female | E19: 54 | F19: 537962 | G19: 01-Mar-2020 | H19: amaka.nnamdi@company.com | I19: Active
A20: EMP0086 | B20: daniel okafor | C20: Marketting | D20: Male | F20: 431814 | G20: 09-Aug-2020 | H20: daniel.okafor@company.com | I20: INACTIVE
A21: EMP0192 | B21: Aisha Chukwu | C21: it | D21: FEMALE | E21: 28 | F21: 312007 | G21: 10/01/2020 | H21: aisha.chukwu@company.com | I21: active
A22: EMP0223 | B22: Esther Abubakar | C22: hr | D22: Male | E22: 36 | F22: 945657 | G22: 07-Nov-2024 | H22: esther.abubakar@company.com | I22: ACTIVE
A23: EMP0337 | B23: MARY OBI | C23: CS | D23: m | E23: 51 | F23: 900939 | G23: 2024-02-22 | H23: mary.obi@company.com | I23: Active
A24: EMP0343 | B24: ESTHER ADAMU | C24: customer service | D24: M | E24: 24 | F24: 297468 | G24: 08-Apr-2019 | H24: esther.adamu@company.com | I24: Left
A25: EMP0277 | B25: YUSUF YAKUBU | C25: it | D25: FEMALE | E25: 33 | F25: 197316 | G25: 06/02/2023 | H25: yusuf.yakubu@company.com | I25: Left
A26: EMP0310 | B26: MUSA YAKUBU | C26: Fin. | D26: female | E26: 47 | F26: 781149 | G26: 2018-05-11 | H26: musa.yakubu@company.com | I26: ACTIVE
A27: EMP0250 | B27: Blessing Ajayi | C27: sales | D27: male | E27: 39 | F27: 677491 | G27: 30-May-2022 | H27: blessing.ajayi@company.com | I27: Terminated
A28: EMP0228 | B28: Chinedu Sani | C28: H.R. | D28: F | E28: 29 | F28: 464749 | G28: 16-Dec-2019 | H28: chinedu.sani@company.com | I28: Act.
A29: EMP0246 | B29: James Obi | C29: SALES | D29: m | E29: 23 | F29: ₦115,365 | G29: 23-Oct-2019 | H29: james.obi@company.com | I29: Active
A30: EMP0352 | B30: victor obi | C30: Operations | D30: M | E30: 54 | F30: 100793 | G30: 2022-12-11 | H30: victor.obi@company.com | I30: Act.
A31: EMP0109 | B31: Ahmed Sani | C31: IT | D31: Male | E31: 46 | F31: 910130 | G31: 20/11/2021 | H31: ahmed.sani@company.com | I31: Act.
A32: EMP0396 | B32: David Eze | C32: sales | D32: Male | E32: 54 | F32: 755699 | G32: 12/05/2019 | H32: david.eze@company.com | I32: ACTIVE
A33: EMP0130 | B33: Gabriel Uche | C33: it | D33: female | E33: 37 | F33: 119710 | G33: 26-Aug-2024 | H33: gabriel.uche@company.com | I33: Act.
A34: EMP0116 | B34: Victor Adamu | C34: IT | D34: female | E34: 24 | F34: 907354 | G34: 2020-02-17 | H34: victor.adamu@company.com | I34: Active
A35: EMP0169 | B35: Ruth Okafor | C35: finance | D35: FEMALE | E35: 42 | F35: 639677 | G35: 11-Jun-2022 | H35: ruth.okafor@company.com | I35: ACTIVE
A36: EMP0067 | B36: John Umeh | C36: H.R. | D36: m | E36: 25 | F36: 50799700 | G36: 2018-05-09 | H36: john.umeh@company.com | I36: active
A37: EMP0229 | B37: james nnamdi | C37: OPERATIONS | D37: F | F37: 267096 | G37: 2024-05-25 | H37: james.nnamdi@company.com | I37: Active
A38: EMP0377 | B38: PETER LAWAL | C38: IT | D38: male | E38: 55 | F38: ₦866,471 | G38: 2024-04-14 | H38: peter.lawal @company.com | I38: Active
A39: EMP0334 | B39: aisha adeyemi | C39: Customer Service | D39: m | E39: 41 | F39: 318993 | G39: 20/10/2024 | H39: aisha.adeyemi@company.com | I39: ACTIVE
A40: EMP0288 | B40: John Okafor | C40: Customer Service | D40: m | E40: 39 | F40: 559284 | G40: 11-Aug-2018 | H40: john.okaforcompany.com | I40: Active
A41: EMP0071 | B41: Ngozi Nnamdi | C41: Finance | D41: MALE | E41: 23 | F41: 586185 | G41: 20/05/2021 | H41: ngozi.nnamdi@company.com | I41: active
A42: EMP0312 | B42: EMMANUEL BELLO | C42: I.T. | D42: Male | E42: 47 | F42: 345475 | G42: 25-Nov-2018 | H42: emmanuel.bello@company.com | I42: active
A43: EMP0264 | B43: joy ajayi | C43: Opperations | D43: MALE | E43: 45 | F43: 596940 | G43: 11/04/2025 | H43: joy.ajayi@company.com | I43: Act.
...

Sheet Lookup_Tables
A1: Standardization Lookup Tables
A2: Maps every raw variant found in the data to one standardized value
A4: Department (raw, upper) | B4: Standardized Value | D4: Gender (raw, upper) | E4: Standardized Value | G4: Status (raw, upper) | H4: Standardized Value
A5: SALES | B5: Sales | D5: M | E5: Male | G5: ACTIVE | H5: Active
A6: SALE | B6: Sales | D6: MALE | E6: Male | G6: ACT. | H6: Active
A7: FINANCE | B7: Finance | D7: F | E7: Female | G7: INACTIVE | H7: Inactive
A8: FIN. | B8: Finance | D8: FEMALE | E8: Female | G8: TERMINATED | H8: Inactive
A9: FINANACE | B9: Finance | G9: LEFT | H9: Inactive
A10: OPERATIONS | B10: Operations
A11: OPS | B11: Operations
A12: OPPERATIONS | B12: Operations
A13: HR | B13: HR
A14: H.R. | B14: HR
A15: HUMAN RESOURCES | B15: HR
A16: IT | B16: IT
A17: I.T. | B17: IT
A18: INFOTECH | B18: IT
A19: MARKETING | B19: Marketing
A20: MKTG | B20: Marketing
A21: MARKETTING | B21: Marketing
... A24: CUST. SERVICE | B24: Customer Service

Sheet Clean_Data (After)
A1: Employee Records — Cleaned & Validated (After)
A2: Every value is a live formula pulling from Raw_Data and the standardization lookup tables
A4: EmployeeID | B4: Clean Name | C4: Clean Department | D4: Clean Gender | E4: Age | F4: Age Valid? | G4: Clean Salary | H4: Salary Valid? | I4: Clean Hire Date | J4: Date Valid? | K4: Email Valid? | L4: Clean Status | M4: Duplicate Record? | N4: Overall Status
A5: ='Raw_Data (Before)'!A5 -> EMP0038 | B5: =PROPER(TRIM('Raw_Data (Before)'!B5)) -> Yusuf Ogundipe | C5: =IFERROR(INDEX(Lookup_Tables!$B$5:$B$24,MATCH(UPPER(TRIM('Raw_Data (Before)'!C5)),Lookup_Tables!$A$5:$A$24,0)),"UNMAPPED") -> Finance | D5: =IFERROR(INDEX(Lookup_Tables!$E$5:$E$8,MATCH(UPPER(TRIM('Raw_Data (Before)'!D5)),Lookup_Tables!$D$5:$D$8,0)),"UNMAPPED") -> Female | E5: ='Raw_Data (Before)'!E5 -> 38 | F5: =IF(E5="","No",IF(OR(E5<16,E5>75),"No","Yes")) -> Yes | G5: =IFERROR(VALUE(SUBSTITUTE(SUBSTITUTE('Raw_Data (Before)'!F5,"₦",""),",","")),"") -> -784644 | H5: =IF(G5="","No",IF(OR(G5<=0,G5>5000000),"No","Yes")) -> No | I5: =IFERROR(DATEVALUE('Raw_Data (Before)'!G5),"") -> 43152 | J5: =IF(I5="","No","Yes") -> Yes | K5: =IF(OR(ISERROR(FIND("@",'Raw_Data (Before)'!H5)),ISNUMBER(FIND("@@",'Raw_Data (Before)'!H5)),ISNUMBER(FIND(" ",'Raw_Data (Before)'!H5)),ISERROR(FIND(".",'Raw_Data (Before)'!H5,FIND("@",'Raw_Data (Before)'!H5)))),"No","Yes") -> Yes | L5: =IFERROR(INDEX(Lookup_Tables!$H$5:$H$9,MATCH(UPPER(TRIM('Raw_Data (Before)'!I5)),Lookup_Tables!$G$5:$G$9,0)),"UNMAPPED") -> Active | M5: =IF(COUNTIF('Raw_Data (Before)'!$A$5:$A$424,A5)>1,"YES","No") -> No | N5: =IF(OR(C5="UNMAPPED",D5="UNMAPPED",F5="No",H5="No",J5="No",K5="No",L5="UNMAPPED",M5="YES"),"NEEDS REVIEW","OK") -> NEEDS REVIEW
A6: ='Raw_Data (Before)'!A6 -> EMP0375 | B6: =PROPER(TRIM('Raw_Data (Before)'!B6)) -> Esther Abubakar | C6: =IFERROR(INDEX(Lookup_Tables!$B$5:$B$24,MATCH(UPPER(TRIM('Raw_Data (Before)'!C6)),Lookup_Tables!$A$5:$A$24,0)),"UNMAPPED") -> Marketing | D6: =IFERROR(INDEX(Lookup_Tables!$E$5:$E$8,MATCH(UPPER(TRIM('Raw_Data (Before)'!D6)),Lookup_Tables!$D$5:$D$8,0)),"UNMAPPED") -> Male | E6: ='Raw_Data (Before)'!E6 -> 53 | F6: =IF(E6="","No",IF(OR(E6<16,E6>75),"No","Yes")) -> Yes | G6: =IFERROR(VALUE(SUBSTITUTE(SUBSTITUTE('Raw_Data (Before)'!F6,"₦",""),",","")),"") -> 235107 | H6: =IF(G6="","No",IF(OR(G6<=0,G6>5000000),"No","Yes")) -> Yes | I6: =IFERROR(DATEVALUE('Raw_Data (Before)'!G6),"") -> 43553 | J6: =IF(I6="","No","Yes") -> Yes | K6: =IF(OR(ISERROR(FIND("@",'Raw_Data (Before)'!H6)),ISNUMBER(FIND("@@",'Raw_Data (Before)'!H6)),ISNUMBER(FIND(" ",'Raw_Data (Before)'!H6)),ISERROR(FIND(".",'Raw_Data (Before)'!H6,FIND("@",'Raw_Data (Before)'!H6)))),"No","Yes") -> Yes | L6: =IFERROR(INDEX(Lookup_Tables!$H$5:$H$9,MATCH(UPPER(TRIM('Raw_Data (Before)'!I6)),Lookup_Tables!$G$5:$G$9,0)),"UNMAPPED") -> Active | M6: =IF(COUNTIF('Raw_Data (Before)'!$A$5:$A$424,A6)>1,"YES","No") -> No | N6: =IF(OR(C6="UNMAPPED",D6="UNMAPPED",F6="No",H6="No",J6="No",K6="No",L6="UNMAPPED",M6="YES"),"NEEDS REVIEW","OK") -> OK
A7: ='Raw_Data (Before)'!A7 -> EMP0110 | B7: =PROPER(TRIM('Raw_Data (Before)'!B7)) -> Chinedu Adamu | C7: =IFERROR(INDEX(Lookup_Tables!$B$5:$B$24,MATCH(UPPER(TRIM('Raw_Data (Before)'!C7)),Lookup_Tables!$A$5:$A$24,0)),"UNMAPPED") -> Customer Service | D7: =IFERROR(INDEX(Lookup_Tables!$E$5:$E$8,MATCH(UPPER(TRIM('Raw_Data (Before)'!D7)),Lookup_Tables!$D$5:$D$8,0)),"UNMAPPED") -> Male | E7: ='Raw_Data (Before)'!E7 -> 56 | F7: =IF(E7="","No",IF(OR(E7<16,E7>75),"No","Yes")) -> Yes | G7: =IFERROR(VALUE(SUBSTITUTE(SUBSTITUTE('Raw_Data (Before)'!F7,"₦",""),",","")),"") -> 204175 | H7: =IF(G7="","No",IF(OR(G7<=0,G7>5000000),"No","Yes")) -> Yes | I7: =IFERROR(DATEVALUE('Raw_Data (Before)'!G7),"") -> 44897 | J7: =IF(I7="","No","Yes") -> Yes | K7: =IF(OR(ISERROR(FIND("@",'Raw_Data (Before)'!H7)),ISNUMBER(FIND("@@",'Raw_Data (Before)'!H7)),ISNUMBER(FIND(" ",'Raw_Data (Before)'!H7)),ISERROR(FIND(".",'Raw_Data (Before)'!H7,FIND("@",'Raw_Data (Before)'!H7)))),"No","Yes") -> Yes | L7: =IFERROR(INDEX(Lookup_Tables!$H$5:$H$9,MATCH(UPPER(TRIM('Raw_Data (Before)'!I7)),Lookup_Tables!$G$5:$G$9,0)),"UNMAPPED") -> Active | M7: =IF(COUNTIF('Raw_Data (Before)'!$A$5:$A$424,A7)>1,"YES","No") -> No | N7: =IF(OR(C7="UNMAPPED",D7="UNMAPPED",F7="No",H7="No",J7="No",K7="No",L7="UNMAPPED",M7="YES"),"NEEDS REVIEW","OK") -> OK
A8: ='Raw_Data (Before)'!A8 -> EMP0046 | B8: =PROPER(TRIM('Raw_Data (Before)'!B8)) -> Yusuf Nwosu | C8: =IFERROR(INDEX(Lookup_Tables!$B$5:$B$24,MATCH(UPPER(TRIM('Raw_Data (Before)'!C8)),Lookup_Tables!$A$5:$A$24,0)),"UNMAPPED") -> IT | D8: =IFERROR(INDEX(Lookup_Tables!$E$5:$E$8,MATCH(UPPER(TRIM('Raw_Data (Before)'!D8)),Lookup_Tables!$D$5:$D$8,0)),"UNMAPPED") -> Male | E8: ='Raw_Data (Before)'!E8 -> 36 | F8: =IF(E8="","No",IF(OR(E8<16,E8>75),"No","Yes")) -> Yes | G8: =IFERROR(VALUE(SUBSTITUTE(SUBSTITUTE('Raw_Data (Before)'!F8,"₦",""),",","")),"") -> 175121 | H8: =IF(G8="","No",IF(OR(G8<=0,G8>5000000),"No","Yes")) -> Yes | I8: =IFERROR(DATEVALUE('Raw_Data (Before)'!G8),"") | J8: =IF(I8="","No","Yes") -> No | K8: =IF(OR(ISERROR(FIND("@",'Raw_Data (Before)'!H8)),ISNUMBER(FIND("@@",'Raw_Data (Before)'!H8)),ISNUMBER(FIND(" ",'Raw_Data (Before)'!H8)),ISERROR(FIND(".",'Raw_Data (Before)'!H8,FIND("@",'Raw_Data (Before)'!H8)))),"No","Yes") -> Yes | L8: =IFERROR(INDEX(Lookup_Tables!$H$5:$H$9,MATCH(UPPER(TRIM('Raw_Data (Before)'!I8)),Lookup_Tables!$G$5:$G$9,0)),"UNMAPPED") -> Inactive | M8: =IF(COUNTIF('Raw_Data (Before)'!$A$5:$A$424,A8)>1,"YES","No") -> No | N8: =IF(OR(C8="UNMAPPED",D8="UNMAPPED",F8="No",H8="No",J8="No",K8="No",L8="UNMAPPED",M8="YES"),"NEEDS REVIEW","OK") -> NEEDS REVIEW
A9: ='Raw_Data (Before)'!A9 -> EMP0092 | B9: =PROPER(TRIM('Raw_Data (Before)'!B9)) -> Ahmed Umeh | C9: =IFERROR(INDEX(Lookup_Tables!$B$5:$B$24,MATCH(UPPER(TRIM('Raw_Data (Before)'!C9)),Lookup_Tables!$A$5:$A$24,0)),"UNMAPPED") -> Operations | D9: =IFERROR(INDEX(Lookup_Tables!$E$5:$E$8,MATCH(UPPER(TRIM('Raw_Data (Before)'!D9)),Lookup_Tables!$D$5:$D$8,0)),"UNMAPPED") -> Female | E9: ='Raw_Data (Before)'!E9 -> 41 | F9: =IF(E9="","No",IF(OR(E9<16,E9>75),"No","Yes")) -> Yes | G9: =IFERROR(VALUE(SUBSTITUTE(SUBSTITUTE('Raw_Data (Before)'!F9,"₦",""),",","")),"") -> 886603 | H9: =IF(G9="","No",IF(OR(G9<=0,G9>5000000),"No","Yes")) -> Yes | I9: =IFERROR(DATEVALUE('Raw_Data (Before)'!G9),"") -> 43299 | J9: =IF(I9="","No","Yes") -> Yes | K9: =IF(OR(ISERROR(FIND("@",'Raw_Data (Before)'!H9)),ISNUMBER(FIND("@@",'Raw_Data (Before)'!H9)),ISNUMBER(FIND(" ",'Raw_Data (Before)'!H9)),ISERROR(FIND(".",'Raw_Data (Before)'!H9,FIND("@",'Raw_Data (Before)'!H9)))),"No","Yes") -> Yes | L9: =IFERROR(INDEX(Lookup_Tables!$H$5:$H$9,MATCH(UPPER(TRIM('Raw_Data (Before)'!I9)),Lookup_Tables!$G$5:$G$9,0)),"UNMAPPED") -> Active | M9: =IF(COUNTIF('Raw_Data (Before)'!$A$5:$A$424,A9)>1,"YES","No") -> No | N9: =IF(OR(C9="UNMAPPED",D9="UNMAPPED",F9="No",H9="No",J9="No",K9="No",L9="UNMAPPED",M9="YES"),"NEEDS REVIEW","OK") -> OK
A10: ='Raw_Data (Before)'!A10 -> EMP0324 | B10: =PROPER(TRIM('Raw_Data (Before)'!B10)) -> Daniel Ajayi | C10: =IFERROR(INDEX(Lookup_Tables!$B$5:$B$24,MATCH(UPPER(TRIM('Raw_Data (Before)'!C10)),Lookup_Tables!$A$5:$A$24,0)),"UNMAPPED") -> IT | D10: =IFERROR(INDEX(Lookup_Tables!$E$5:$E$8,MATCH(UPPER(TRIM('Raw_Data (Before)'!D10)),Lookup_Tables!$D$5:$D$8,0)),"UNMAPPED") -> Female | E10: ='Raw_Data (Before)'!E10 -> 50 | F10: =IF(E10="","No",IF(OR(E10<16,E10>75),"No","Yes")) -> Yes | G10: =IFERROR(VALUE(SUBSTITUTE(SUBSTITUTE('Raw_Data (Before)'!F10,"₦",""),",","")),"") -> 332625 | H10: =IF(G10="","No",IF(OR(G10<=0,G10>5000000),"No","Yes")) -> Yes | I10: =IFERROR(DATEVALUE('Raw_Data (Before)'!G10),"") -> 43890 | J10: =IF(I10="","No","Yes") -> Yes | K10: =IF(OR(ISERROR(FIND("@",'Raw_Data (Before)'!H10)),ISNUMBER(FIND("@@",'Raw_Data (Before)'!H10)),ISNUMBER(FIND(" ",'Raw_Data (Before)'!H10)),ISERROR(FIND(".",'Raw_Data (Before)'!H10,FIND("@",'Raw_Data (Before)'!H10)))),"No","Yes") -> Yes | L10: =IFERROR(INDEX(Lookup_Tables!$H$5:$H$9,MATCH(UPPER(TRIM('Raw_Data (Before)'!I10)),Lookup_Tables!$G$5:$G$9,0)),"UNMAPPED") -> Active | M10: =IF(COUNTIF('Raw_Data (Before)'!$A$5:$A$424,A10)>1,"YES","No") -> No | N10: =IF(OR(C10="UNMAPPED",D10="UNMAPPED",F10="No",H10="No",J10="No",K10="No",L10="UNMAPPED",M10="YES"),"NEEDS REVIEW","OK") -> OK
A11: ='Raw_Data (Before)'!A11 -> EMP0098 | B11: =PROPER(TRIM('Raw_Data (Before)'!B11)) -> Hauwa Nwosu | C11: =IFERROR(INDEX(Lookup_Tables!$B$5:$B$24,MATCH(UPPER(TRIM('Raw_Data (Before)'!C11)),Lookup_Tables!$A$5:$A$24,0)),"UNMAPPED") -> Operations | D11: =IFERROR(INDEX(Lookup_Tables!$E$5:$E$8,MATCH(UPPER(TRIM('Raw_Data (Before)'!D11)),Lookup_Tables!$D$5:$D$8,0)),"UNMAPPED") -> Male | E11: ='Raw_Data (Before)'!E11 -> 36 | F11: =IF(E11="","No",IF(OR(E11<16,E11>75),"No","Yes")) -> Yes | G11: =IFERROR(VALUE(SUBSTITUTE(SUBSTITUTE('Raw_Data (Before)'!F11,"₦",""),",","")),"") -> 424011 | H11: =IF(G11="","No",IF(OR(G11<=0,G11>5000000),"No","Yes")) -> Yes | I11: =IFERROR(DATEVALUE('Raw_Data (Before)'!G11),"") -> 45570 | J11: =IF(I11="","No","Yes") -> Yes | K11: =IF(OR(ISERROR(FIND("@",'Raw_Data (Before)'!H11)),ISNUMBER(FIND("@@",'Raw_Data (Before)'!H11)),ISNUMBER(FIND(" ",'Raw_Data (Before)'!H11)),ISERROR(FIND(".",'Raw_Data (Before)'!H11,FIND("@",'Raw_Data (Before)'!H11)))),"No","Yes") -> Yes | L11: =IFERROR(INDEX(Lookup_Tables!$H$5:$H$9,MATCH(UPPER(TRIM('Raw_Data (Before)'!I11)),Lookup_Tables!$G$5:$G$9,0)),"UNMAPPED") -> Inactive | M11: =IF(COUNTIF('Raw_Data (Before)'!$A$5:$A$424,A11)>1,"YES","No") -> No | N11: =IF(OR(C11="UNMAPPED",D11="UNMAPPED",F11="No",H11="No",J11="No",K11="No",L11="UNMAPPED",M11="YES"),"NEEDS REVIEW","OK") -> OK
A12: ='Raw_Data (Before)'!A12 -> EMP0326 | B12: =PROPER(TRIM('Raw_Data (Before)'!B12)) -> Samuel Bello | C12: =IFERROR(INDEX(Lookup_Tables!$B$5:$B$24,MATCH(UPPER(TRIM('Raw_Data (Before)'!C12)),Lookup_Tables!$A$5:$A$24,0)),"UNMAPPED") -> Finance | D12: =IFERROR(INDEX(Lookup_Tables!$E$5:$E$8,MATCH(UPPER(TRIM('Raw_Data (Before)'!D12)),Lookup_Tables!$D$5:$D$8,0)),"UNMAPPED") -> Male | E12: ='Raw_Data (Before)'!E12 -> 40 | F12: =IF(E12="","No",IF(OR(E12<16,E12>75),"No","Yes")) -> Yes | G12: =IFERROR(VALUE(SUBSTITUTE(SUBSTITUTE('Raw_Data (Before)'!F12,"₦",""),",","")),"") -> 138360 | H12: =IF(G12="","No",IF(OR(G12<=0,G12>5000000),"No","Yes")) -> Yes | I12: =IFERROR(DATEVALUE('Raw_Data (Before)'!G12),"") -> 44725 | J12: =IF(I12="","No","Yes") -> Yes | K12: =IF(OR(ISERROR(FIND("@",'Raw_Data (Before)'!H12)),ISNUMBER(FIND("@@",'Raw_Data (Before)'!H12)),ISNUMBER(FIND(" ",'Raw_Data (Before)'!H12)),ISERROR(FIND(".",'Raw_Data (Before)'!H12,FIND("@",'Raw_Data (Before)'!H12)))),"No","Yes") -> Yes | L12: =IFERROR(INDEX(Lookup_Tables!$H$5:$H$9,MATCH(UPPER(TRIM('Raw_Data (Before)'!I12)),Lookup_Tables!$G$5:$G$9,0)),"UNMAPPED") -> Active | M12: =IF(COUNTIF('Raw_Data (Before)'!$A$5:$A$424,A12)>1,"YES","No") -> No | N12: =IF(OR(C12="UNMAPPED",D12="UNMAPPED",F12="No",H12="No",J12="No",K12="No",L12="UNMAPPED",M12="YES"),"NEEDS REVIEW","OK") -> OK
A13: ='Raw_Data (Before)'!A13 -> EMP0358 | B13: =PROPER(TRIM('Raw_Data (Before)'!B13)) -> Peter Chukwu | C13: =IFERROR(INDEX(Lookup_Tables!$B$5:$B$24,MATCH(UPPER(TRIM('Raw_Data (Before)'!C13)),Lookup_Tables!$A$5:$A$24,0)),"UNMAPPED") -> Marketing | D13: =IFERROR(INDEX(Lookup_Tables!$E$5:$E$8,MATCH(UPPER(TRIM('Raw_Data (Before)'!D13)),Lookup_Tables!$D$5:$D$8,0)),"UNMAPPED") -> Female | E13: ='Raw_Data (Before)'!E13 -> 57 | F13: =IF(E13="","No",IF(OR(E13<16,E13>75),"No","Yes")) -> Yes | G13: =IFERROR(VALUE(SUBSTITUTE(SUBSTITUTE('Raw_Data (Before)'!F13,"₦",""),",","")),"") -> 94473 | H13: =IF(G13="","No",IF(OR(G13<=0,G13>5000000),"No","Yes")) -> Yes | I13: =IFERROR(DATEVALUE('Raw_Data (Before)'!G13),"") -> 44901 | J13: =IF(I13="","No","Yes") -> Yes | K13: =IF(OR(ISERROR(FIND("@",'Raw_Data (Before)'!H13)),ISNUMBER(FIND("@@",'Raw_Data (Before)'!H13)),ISNUMBER(FIND(" ",'Raw_Data (Before)'!H13)),ISERROR(FIND(".",'Raw_Data (Before)'!H13,FIND("@",'Raw_Data (Before)'!H13)))),"No","Yes") -> Yes | L13: =IFERROR(INDEX(Lookup_Tables!$H$5:$H$9,MATCH(UPPER(TRIM('Raw_Data (Before)'!I13)),Lookup_Tables!$G$5:$G$9,0)),"UNMAPPED") -> Active | M13: =IF(COUNTIF('Raw_Data (Before)'!$A$5:$A$424,A13)>1,"YES","No") -> No | N13: =IF(OR(C13="UNMAPPED",D13="UNMAPPED",F13="No",H13="No",J13="No",K13="No",L13="UNMAPPED",M13="YES"),"NEEDS REVIEW","OK") -> OK
A14: ='Raw_Data (Before)'!A14 -> EMP0266 | B14: =PROPER(TRIM('Raw_Data (Before)'!B14)) -> Bisi Uche | C14: =IFERROR(INDEX(Lookup_Tables!$B$5:$B$24,MATCH(UPPER(TRIM('Raw_Data (Before)'!C14)),Lookup_Tables!$A$5:$A$24,0)),"UNMAPPED") -> Operations | D14: =IFERROR(INDEX(Lookup_Tables!$E$5:$E$8,MATCH(UPPER(TRIM('Raw_Data (Before)'!D14)),Lookup_Tables!$D$5:$D$8,0)),"UNMAPPED") -> Female | E14: ='Raw_Data (Before)'!E14 -> 49 | F14: =IF(E14="","No",IF(OR(E14<16,E14>75),"No","Yes")) -> Yes | G14: =IFERROR(VALUE(SUBSTITUTE(SUBSTITUTE('Raw_Data (Before)'!F14,"₦",""),",","")),"") -> 50265600 | H14: =IF(G14="","No",IF(OR(G14<=0,G14>5000000),"No","Yes")) -> No | I14: =IFERROR(DATEVALUE('Raw_Data (Before)'!G14),"") -> 43909 | J14: =IF(I14="","No","Yes") -> Yes | K14: =IF(OR(ISERROR(FIND("@",'Raw_Data (Before)'!H14)),ISNUMBER(FIND("@@",'Raw_Data (Before)'!H14)),ISNUMBER(FIND(" ",'Raw_Data (Before)'!H14)),ISERROR(FIND(".",'Raw_Data (Before)'!H14,FIND("@",'Raw_Data (Before)'!H14)))),"No","Yes") -> Yes | L14: =IFERROR(INDEX(Lookup_Tables!$H$5:$H$9,MATCH(UPPER(TRIM('Raw_Data (Before)'!I14)),Lookup_Tables!$G$5:$G$9,0)),"UNMAPPED") -> Active | M14: =IF(COUNTIF('Raw_Data (Before)'!$A$5:$A$424,A14)>1,"YES","No") -> No | N14: =IF(OR(C14="UNMAPPED",D14="UNMAPPED",F14="No",H14="No",J14="No",K14="No",L14="UNMAPPED",M14="YES"),"NEEDS REVIEW","OK") -> NEEDS REVIEW
A15: ='Raw_Data (Before)'!A15 -> EMP0156 | B15: =PROPER(TRIM('Raw_Data (Before)'!B15)) -> Aisha Lawal | C15: =IFERROR(INDEX(Lookup_Tables!$B$5:$B$24,MATCH(UPPER(TRIM('Raw_Data (Before)'!C15)),Lookup_Tables!$A$5:$A$24,0)),"UNMAPPED") -> Sales | D15: =IFERROR(INDEX(Lookup_Tables!$E$5:$E$8,MATCH(UPPER(TRIM('Raw_Data (Before)'!D15)),Lookup_Tables!$D$5:$D$8,0)),"UNMAPPED") -> Male | E15: ='Raw_Data (Before)'!E15 -> 59 | F15: =IF(E15="","No",IF(OR(E15<16,E15>75),"No","Yes")) -> Yes | G15: =IFERROR(VALUE(SUBSTITUTE(SUBSTITUTE('Raw_Data (Before)'!F15,"₦",""),",","")),"") -> 196419 | H15: =IF(G15="","No",IF(OR(G15<=0,G15>5000000),"No","Yes")) -> Yes | I15: =IFERROR(DATEVALUE('Raw_Data (Before)'!G15),"") -> 44812 | J15: =IF(I15="","No","Yes") -> Yes | K15: =IF(OR(ISERROR(FIND("@",'Raw_Data (Before)'!H15)),ISNUMBER(FIND("@@",'Raw_Data (Before)'!H15)),ISNUMBER(FIND(" ",'Raw_Data (Before)'!H15)),ISERROR(FIND(".",'Raw_Data (Before)'!H15,FIND("@",'Raw_Data (Before)'!H15)))),"No","Yes") -> Yes | L15: =IFERROR(INDEX(Lookup_Tables!$H$5:$H$9,MATCH(UPPER(TRIM('Raw_Data (Before)'!I15)),Lookup_Tables!$G$5:$G$9,0)),"UNMAPPED") -> Active | M15: =IF(COUNTIF('Raw_Data (Before)'!$A$5:$A$424,A15)>1,"YES","No") -> No | N15: =IF(OR(C15="UNMAPPED",D15="UNMAPPED",F15="No",H15="No",J15="No",K15="No",L15="UNMAPPED",M15="YES"),"NEEDS REVIEW","OK") -> OK
A16: ='Raw_Data (Before)'!A16 -> EMP0217 | B16: =PROPER(TRIM('Raw_Data (Before)'!B16)) -> Ola Ogundipe | C16: =IFERROR(INDEX(Lookup_Tables!$B$5:$B$24,MATCH(UPPER(TRIM('Raw_Data (Before)'!C16)),Lookup_Tables!$A$5:$A$24,0)),"UNMAPPED") -> IT | D16: =IFERROR(INDEX(Lookup_Tables!$E$5:$E$8,MATCH(UPPER(TRIM('Raw_Data (Before)'!D16)),Lookup_Tables!$D$5:$D$8,0)),"UNMAPPED") -> Male | E16: ='Raw_Data (Before)'!E16 -> 49 | F16: =IF(E16="","No",IF(OR(E16<16,E16>75),"No","Yes")) -> Yes | G16: =IFERROR(VALUE(SUBSTITUTE(SUBSTITUTE('Raw_Data (Before)'!F16,"₦",""),",","")),"") -> 271152 | H16: =IF(G16="","No",IF(OR(G16<=0,G16>5000000),"No","Yes")) -> Yes | I16: =IFERROR(DATEVALUE('Raw_Data (Before)'!G16),"") | J16: =IF(I16="","No","Yes") -> No | K16: =IF(OR(ISERROR(FIND("@",'Raw_Data (Before)'!H16)),ISNUMBER(FIND("@@",'Raw_Data (Before)'!H16)),ISNUMBER(FIND(" ",'Raw_Data (Before)'!H16)),ISERROR(FIND(".",'Raw_Data (Before)'!H16,FIND("@",'Raw_Data (Before)'!H16)))),"No","Yes") -> Yes | L16: =IFERROR(INDEX(Lookup_Tables!$H$5:$H$9,MATCH(UPPER(TRIM('Raw_Data (Before)'!I16)),Lookup_Tables!$G$5:$G$9,0)),"UNMAPPED") -> Active | M16: =IF(COUNTIF('Raw_Data (Before)'!$A$5:$A$424,A16)>1,"YES","No") -> No | N16: =IF(OR(C16="UNMAPPED",D16="UNMAPPED",F16="No",H16="No",J16="No",K16="No",L16="UNMAPPED",M16="YES"),"NEEDS REVIEW","OK") -> NEEDS REVIEW
... A424: ='Raw_Data (Before)'!A424 -> EMP0376 | B424: =PROPER(TRIM('Raw_Data (Before)'!B424)) -> Grace Adeyemi | C424: =IFERROR(INDEX(Lookup_Tables!$B$5:$B$24,MATCH(UPPER(TRIM('Raw_Data (Before)'!C424)),Lookup_Tables!$A$5:$A$24,0)),"UNMAPPED") -> HR | D424: =IFERROR(INDEX(Lookup_Tables!$E$5:$E$8,MATCH(UPPER(TRIM('Raw_Data (Before)'!D424)),Lookup_Tables!$D$5:$D$8,0)),"UNMAPPED") -> Female | E424: ='Raw_Data (Before)'!E424 -> 44 | F424: =IF(E424="","No",IF(OR(E424<16,E424>75),"No","Yes")) -> Yes | G424: =IFERROR(VALUE(SUBSTITUTE(SUBSTITUTE('Raw_Data (Before)'!F424,"₦",""),",","")),"") -> 347459 | H424: =IF(G424="","No",IF(OR(G424<=0,G424>5000000),"No","Yes")) -> Yes | I424: =IFERROR(DATEVALUE('Raw_Data (Before)'!G424),"") -> 45476 | J424: =IF(I424="","No","Yes") -> Yes | K424: =IF(OR(ISERROR(FIND("@",'Raw_Data (Before)'!H424)),ISNUMBER(FIND("@@",'Raw_Data (Before)'!H424)),ISNUMBER(FIND(" ",'Raw_Data (Before)'!H424)),ISERROR(FIND(".",'Raw_Data (Before)'!H424,FIND("@",'Raw_Data (Before)'!H424)))),"No","Yes") -> Yes | L424: =IFERROR(INDEX(Lookup_Tables!$H$5:$H$9,MATCH(UPPER(TRIM('Raw_Data (Before)'!I424)),Lookup_Tables!$G$5:$G$9,0)),"UNMAPPED") -> Active | M424: =IF(COUNTIF('Raw_Data (Before)'!$A$5:$A$424,A424)>1,"YES","No") -> No | N424: =IF(OR(C424="UNMAPPED",D424="UNMAPPED",F424="No",H424="No",J424="No",K424="No",L424="UNMAPPED",M424="YES"),"NEEDS REVIEW","OK") -> OK

Sheet Before_After_Summary
A1: Before / After Data Quality Summary
A2: Quantified impact of the cleaning process
A4: Metric | B4: Value
A5: Total records | B5: =COUNTA('Clean_Data (After)'!A5:A424) -> 420
A6: Records needing review (after cleaning) | B6: =COUNTIF('Clean_Data (After)'!N5:N424,"NEEDS REVIEW") -> 187
A7: Clean, ready-to-use records | B7: =COUNTIF('Clean_Data (After)'!N5:N424,"OK") -> 233
A8: Data quality rate (%) | B8: =ROUND(COUNTIF('Clean_Data (After)'!N5:N424,"OK")/COUNTA('Clean_Data (After)'!A5:A424)*100,1) -> 55.5
A9: Duplicate records found | B9: =COUNTIF('Clean_Data (After)'!M5:M424,"YES") -> 40
A10: Invalid / missing ages | B10: =COUNTIF('Clean_Data (After)'!F5:F424,"No") -> 27
A11: Invalid / missing salaries | B11: =COUNTIF('Clean_Data (After)'!H5:H424,"No") -> 38
A12: Invalid / unparseable hire dates | B12: =COUNTIF('Clean_Data (After)'!J5:J424,"No") -> 81
A13: Invalid email addresses | B13: =COUNTIF('Clean_Data (After)'!K5:K424,"No") -> 37
A14: Department/Gender/Status values standardized | B14: =COUNTA('Clean_Data (After)'!A5:A424) -> 420
